2020-10-18 10:07:14,783 INFO    MainThread:1327 [internal.py:wandb_internal():62] W&B internal server running at pid: 1327
2020-10-18 10:07:14,785 INFO    WriterThread:1327 [datastore.py:open_for_write():76] open: wandb/run-20201018_100713-35ullf4b/run-35ullf4b.wandb
2020-10-18 10:07:14,786 DEBUG   HandlerThread:1327 [handler.py:handle_request():54] handle_request: check_version
2020-10-18 10:07:14,787 DEBUG   SenderThread:1327 [sender.py:send():88] send: header
2020-10-18 10:07:14,787 DEBUG   SenderThread:1327 [sender.py:send():88] send: request
2020-10-18 10:07:14,787 DEBUG   SenderThread:1327 [sender.py:send_request():97] send_request: check_version
2020-10-18 10:07:14,792 DEBUG   Thread-4  :1327 [connectionpool.py:_new_conn():943] Starting new HTTPS connection (1): pypi.org:443
2020-10-18 10:07:15,263 DEBUG   Thread-4  :1327 [connectionpool.py:_make_request():442] https://pypi.org:443 "GET /pypi/wandb/json HTTP/1.1" 200 50840
2020-10-18 10:07:15,381 DEBUG   SenderThread:1327 [sender.py:send():88] send: run
2020-10-18 10:07:15,392 DEBUG   SenderThread:1327 [cmd.py:execute():719] Popen(['git', 'cat-file', '--batch-check'], cwd=/Users/shreyasshandilya/Desktop/Shandilya/Padhai/CS6886/assignment3, universal_newlines=False, shell=None, istream=<valid stream>)
2020-10-18 10:07:15,432 DEBUG   SenderThread:1327 [connectionpool.py:_new_conn():943] Starting new HTTPS connection (1): api.wandb.ai:443
2020-10-18 10:07:16,084 DEBUG   SenderThread:1327 [connectionpool.py:_make_request():442] https://api.wandb.ai:443 "POST /graphql HTTP/1.1" 403 None
2020-10-18 10:07:16,092 ERROR   SenderThread:1327 [internal_api.py:execute():131] 403 response executing GraphQL.
2020-10-18 10:07:16,093 ERROR   SenderThread:1327 [internal_api.py:execute():132] {"errors":[{"message":"permission denied","path":["upsertBucket"],"extensions":{"code":"PERMISSION_ERROR"}}],"data":{"upsertBucket":null}}
2020-10-18 10:07:16,387 INFO    WriterThread:1327 [datastore.py:close():257] close: wandb/run-20201018_100713-35ullf4b/run-35ullf4b.wandb
2020-10-18 10:07:16,387 INFO    HandlerThread:1327 [handler.py:finish():267] shutting down handler
2020-10-18 10:07:16,793 ERROR   MainThread:1327 [internal.py:wandb_internal():128] Thread SenderThread:
Traceback (most recent call last):
  File "/Users/shreyasshandilya/Desktop/Shandilya/Padhai/CS6886/assignment3/venv/lib/python3.7/site-packages/wandb/old/retry.py", line 96, in __call__
    result = self._call_fn(*args, **kwargs)
  File "/Users/shreyasshandilya/Desktop/Shandilya/Padhai/CS6886/assignment3/venv/lib/python3.7/site-packages/wandb/internal/internal_api.py", line 134, in execute
    six.reraise(*sys.exc_info())
  File "/Users/shreyasshandilya/Desktop/Shandilya/Padhai/CS6886/assignment3/venv/lib/python3.7/site-packages/six.py", line 703, in reraise
    raise value
  File "/Users/shreyasshandilya/Desktop/Shandilya/Padhai/CS6886/assignment3/venv/lib/python3.7/site-packages/wandb/internal/internal_api.py", line 128, in execute
    return self.client.execute(*args, **kwargs)
  File "/Users/shreyasshandilya/Desktop/Shandilya/Padhai/CS6886/assignment3/venv/lib/python3.7/site-packages/wandb/vendor/gql-0.2.0/gql/client.py", line 52, in execute
    result = self._get_result(document, *args, **kwargs)
  File "/Users/shreyasshandilya/Desktop/Shandilya/Padhai/CS6886/assignment3/venv/lib/python3.7/site-packages/wandb/vendor/gql-0.2.0/gql/client.py", line 60, in _get_result
    return self.transport.execute(document, *args, **kwargs)
  File "/Users/shreyasshandilya/Desktop/Shandilya/Padhai/CS6886/assignment3/venv/lib/python3.7/site-packages/wandb/vendor/gql-0.2.0/gql/transport/requests.py", line 39, in execute
    request.raise_for_status()
  File "/Users/shreyasshandilya/Desktop/Shandilya/Padhai/CS6886/assignment3/venv/lib/python3.7/site-packages/requests/models.py", line 941, in raise_for_status
    raise HTTPError(http_error_msg, response=self)
requests.exceptions.HTTPError: 403 Client Error: Forbidden for url: https://api.wandb.ai/graphql

During handling of the above exception, another exception occurred:

Traceback (most recent call last):
  File "/Users/shreyasshandilya/Desktop/Shandilya/Padhai/CS6886/assignment3/venv/lib/python3.7/site-packages/wandb/apis/normalize.py", line 24, in wrapper
    return func(*args, **kwargs)
  File "/Users/shreyasshandilya/Desktop/Shandilya/Padhai/CS6886/assignment3/venv/lib/python3.7/site-packages/wandb/internal/internal_api.py", line 973, in upsert_run
    response = self.gql(mutation, variable_values=variable_values, **kwargs)
  File "/Users/shreyasshandilya/Desktop/Shandilya/Padhai/CS6886/assignment3/venv/lib/python3.7/site-packages/wandb/old/retry.py", line 105, in __call__
    if not check_retry_fn(e):
  File "/Users/shreyasshandilya/Desktop/Shandilya/Padhai/CS6886/assignment3/venv/lib/python3.7/site-packages/wandb/util.py", line 589, in no_retry_auth
    raise CommError("Permission denied, ask the project owner to grant you access")
wandb.errors.error.CommError: Permission denied, ask the project owner to grant you access

During handling of the above exception, another exception occurred:

Traceback (most recent call last):
  File "/Users/shreyasshandilya/Desktop/Shandilya/Padhai/CS6886/assignment3/venv/lib/python3.7/site-packages/wandb/internal/internal_util.py", line 33, in run
    self._run()
  File "/Users/shreyasshandilya/Desktop/Shandilya/Padhai/CS6886/assignment3/venv/lib/python3.7/site-packages/wandb/internal/internal_util.py", line 60, in _run
    self._process(record)
  File "/Users/shreyasshandilya/Desktop/Shandilya/Padhai/CS6886/assignment3/venv/lib/python3.7/site-packages/wandb/internal/internal.py", line 232, in _process
    self._sm.send(record)
  File "/Users/shreyasshandilya/Desktop/Shandilya/Padhai/CS6886/assignment3/venv/lib/python3.7/site-packages/wandb/internal/sender.py", line 90, in send
    send_handler(record)
  File "/Users/shreyasshandilya/Desktop/Shandilya/Padhai/CS6886/assignment3/venv/lib/python3.7/site-packages/wandb/internal/sender.py", line 360, in send_run
    self._init_run(run, config_dict)
  File "/Users/shreyasshandilya/Desktop/Shandilya/Padhai/CS6886/assignment3/venv/lib/python3.7/site-packages/wandb/internal/sender.py", line 396, in _init_run
    commit=repo.last_commit,
  File "/Users/shreyasshandilya/Desktop/Shandilya/Padhai/CS6886/assignment3/venv/lib/python3.7/site-packages/wandb/apis/normalize.py", line 62, in wrapper
    six.reraise(CommError, CommError(message, err), sys.exc_info()[2])
  File "/Users/shreyasshandilya/Desktop/Shandilya/Padhai/CS6886/assignment3/venv/lib/python3.7/site-packages/six.py", line 702, in reraise
    raise value.with_traceback(tb)
  File "/Users/shreyasshandilya/Desktop/Shandilya/Padhai/CS6886/assignment3/venv/lib/python3.7/site-packages/wandb/apis/normalize.py", line 24, in wrapper
    return func(*args, **kwargs)
  File "/Users/shreyasshandilya/Desktop/Shandilya/Padhai/CS6886/assignment3/venv/lib/python3.7/site-packages/wandb/internal/internal_api.py", line 973, in upsert_run
    response = self.gql(mutation, variable_values=variable_values, **kwargs)
  File "/Users/shreyasshandilya/Desktop/Shandilya/Padhai/CS6886/assignment3/venv/lib/python3.7/site-packages/wandb/old/retry.py", line 105, in __call__
    if not check_retry_fn(e):
  File "/Users/shreyasshandilya/Desktop/Shandilya/Padhai/CS6886/assignment3/venv/lib/python3.7/site-packages/wandb/util.py", line 589, in no_retry_auth
    raise CommError("Permission denied, ask the project owner to grant you access")
wandb.errors.error.CommError: Permission denied, ask the project owner to grant you access
2020-10-18 10:07:16,825 DEBUG   raven-sentry.BackgroundWorker:1327 [connectionpool.py:_new_conn():943] Starting new HTTPS connection (1): o151352.ingest.sentry.io:443
2020-10-18 10:07:18,759 DEBUG   raven-sentry.BackgroundWorker:1327 [connectionpool.py:_make_request():442] https://o151352.ingest.sentry.io:443 "POST /api/5288891/store/ HTTP/1.1" 200 41
2020-10-18 10:07:18,828 INFO    MainThread:1327 [internal.py:handle_exit():137] Internal process exited
